ERROR 2022-12-05 11:45:56,431 django.request.log_response:224- Internal Server Error: /
Traceback (most recent call last):
  File "/usr/local/lib/python3.9/site-packages/django/urls/base.py", line 71, in reverse
    extra, resolver = resolver.namespace_dict[ns]
KeyError: 'djdt'

During handling of the above exception, another exception occurred:

Traceback (most recent call last):
  File "/usr/local/lib/python3.9/site-packages/django/core/handlers/exception.py", line 47, in inner
    response = get_response(request)
  File "/usr/local/lib/python3.9/site-packages/debug_toolbar/middleware.py", line 74, in __call__
    rendered = toolbar.render_toolbar()
  File "/usr/local/lib/python3.9/site-packages/debug_toolbar/toolbar.py", line 82, in render_toolbar
    return render_to_string("debug_toolbar/base.html", context)
  File "/usr/local/lib/python3.9/site-packages/django/template/loader.py", line 62, in render_to_string
    return template.render(context, request)
  File "/usr/local/lib/python3.9/site-packages/django/template/backends/django.py", line 61, in render
    return self.template.render(context)
  File "/usr/local/lib/python3.9/site-packages/django/template/base.py", line 170, in render
    return self._render(context)
  File "/usr/local/lib/python3.9/site-packages/django/test/utils.py", line 100, in instrumented_test_render
    return self.nodelist.render(context)
  File "/usr/local/lib/python3.9/site-packages/django/template/base.py", line 938, in render
    bit = node.render_annotated(context)
  File "/usr/local/lib/python3.9/site-packages/django/template/base.py", line 905, in render_annotated
    return self.render(context)
  File "/usr/local/lib/python3.9/site-packages/django/template/defaulttags.py", line 315, in render
    return nodelist.render(context)
  File "/usr/local/lib/python3.9/site-packages/django/template/base.py", line 938, in render
    bit = node.render_annotated(context)
  File "/usr/local/lib/python3.9/site-packages/django/template/base.py", line 905, in render_annotated
    return self.render(context)
  File "/usr/local/lib/python3.9/site-packages/django/template/defaulttags.py", line 449, in render
    url = reverse(view_name, args=args, kwargs=kwargs, current_app=current_app)
  File "/usr/local/lib/python3.9/site-packages/django/urls/base.py", line 82, in reverse
    raise NoReverseMatch("%s is not a registered namespace" % key)
django.urls.exceptions.NoReverseMatch: 'djdt' is not a registered namespace
ERROR 2022-12-05 11:45:56,434 django.server.log_message:161- "GET / HTTP/1.1" 500 125444
ERROR 2022-12-05 11:48:57,131 django.request.log_response:224- Internal Server Error: /
Traceback (most recent call last):
  File "/usr/local/lib/python3.9/site-packages/django/urls/base.py", line 71, in reverse
    extra, resolver = resolver.namespace_dict[ns]
KeyError: 'djdt'

During handling of the above exception, another exception occurred:

Traceback (most recent call last):
  File "/usr/local/lib/python3.9/site-packages/django/core/handlers/exception.py", line 47, in inner
    response = get_response(request)
  File "/usr/local/lib/python3.9/site-packages/debug_toolbar/middleware.py", line 74, in __call__
    rendered = toolbar.render_toolbar()
  File "/usr/local/lib/python3.9/site-packages/debug_toolbar/toolbar.py", line 82, in render_toolbar
    return render_to_string("debug_toolbar/base.html", context)
  File "/usr/local/lib/python3.9/site-packages/django/template/loader.py", line 62, in render_to_string
    return template.render(context, request)
  File "/usr/local/lib/python3.9/site-packages/django/template/backends/django.py", line 61, in render
    return self.template.render(context)
  File "/usr/local/lib/python3.9/site-packages/django/template/base.py", line 170, in render
    return self._render(context)
  File "/usr/local/lib/python3.9/site-packages/django/test/utils.py", line 100, in instrumented_test_render
    return self.nodelist.render(context)
  File "/usr/local/lib/python3.9/site-packages/django/template/base.py", line 938, in render
    bit = node.render_annotated(context)
  File "/usr/local/lib/python3.9/site-packages/django/template/base.py", line 905, in render_annotated
    return self.render(context)
  File "/usr/local/lib/python3.9/site-packages/django/template/defaulttags.py", line 315, in render
    return nodelist.render(context)
  File "/usr/local/lib/python3.9/site-packages/django/template/base.py", line 938, in render
    bit = node.render_annotated(context)
  File "/usr/local/lib/python3.9/site-packages/django/template/base.py", line 905, in render_annotated
    return self.render(context)
  File "/usr/local/lib/python3.9/site-packages/django/template/defaulttags.py", line 449, in render
    url = reverse(view_name, args=args, kwargs=kwargs, current_app=current_app)
  File "/usr/local/lib/python3.9/site-packages/django/urls/base.py", line 82, in reverse
    raise NoReverseMatch("%s is not a registered namespace" % key)
django.urls.exceptions.NoReverseMatch: 'djdt' is not a registered namespace
ERROR 2022-12-05 11:48:57,136 django.server.log_message:161- "GET / HTTP/1.1" 500 125135
ERROR 2022-12-05 11:52:55,448 django.request.log_response:224- Internal Server Error: /
Traceback (most recent call last):
  File "/usr/local/lib/python3.9/site-packages/django/urls/base.py", line 71, in reverse
    extra, resolver = resolver.namespace_dict[ns]
KeyError: 'djdt'

During handling of the above exception, another exception occurred:

Traceback (most recent call last):
  File "/usr/local/lib/python3.9/site-packages/django/core/handlers/exception.py", line 47, in inner
    response = get_response(request)
  File "/usr/local/lib/python3.9/site-packages/debug_toolbar/middleware.py", line 74, in __call__
    rendered = toolbar.render_toolbar()
  File "/usr/local/lib/python3.9/site-packages/debug_toolbar/toolbar.py", line 82, in render_toolbar
    return render_to_string("debug_toolbar/base.html", context)
  File "/usr/local/lib/python3.9/site-packages/django/template/loader.py", line 62, in render_to_string
    return template.render(context, request)
  File "/usr/local/lib/python3.9/site-packages/django/template/backends/django.py", line 61, in render
    return self.template.render(context)
  File "/usr/local/lib/python3.9/site-packages/django/template/base.py", line 170, in render
    return self._render(context)
  File "/usr/local/lib/python3.9/site-packages/django/test/utils.py", line 100, in instrumented_test_render
    return self.nodelist.render(context)
  File "/usr/local/lib/python3.9/site-packages/django/template/base.py", line 938, in render
    bit = node.render_annotated(context)
  File "/usr/local/lib/python3.9/site-packages/django/template/base.py", line 905, in render_annotated
    return self.render(context)
  File "/usr/local/lib/python3.9/site-packages/django/template/defaulttags.py", line 315, in render
    return nodelist.render(context)
  File "/usr/local/lib/python3.9/site-packages/django/template/base.py", line 938, in render
    bit = node.render_annotated(context)
  File "/usr/local/lib/python3.9/site-packages/django/template/base.py", line 905, in render_annotated
    return self.render(context)
  File "/usr/local/lib/python3.9/site-packages/django/template/defaulttags.py", line 449, in render
    url = reverse(view_name, args=args, kwargs=kwargs, current_app=current_app)
  File "/usr/local/lib/python3.9/site-packages/django/urls/base.py", line 82, in reverse
    raise NoReverseMatch("%s is not a registered namespace" % key)
django.urls.exceptions.NoReverseMatch: 'djdt' is not a registered namespace
ERROR 2022-12-05 11:52:55,455 django.server.log_message:161- "GET / HTTP/1.1" 500 125135
ERROR 2022-12-05 11:52:55,655 django.request.log_response:224- Internal Server Error: /favicon.ico
Traceback (most recent call last):
  File "/usr/local/lib/python3.9/site-packages/django/urls/base.py", line 71, in reverse
    extra, resolver = resolver.namespace_dict[ns]
KeyError: 'djdt'

During handling of the above exception, another exception occurred:

Traceback (most recent call last):
  File "/usr/local/lib/python3.9/site-packages/django/core/handlers/exception.py", line 47, in inner
    response = get_response(request)
  File "/usr/local/lib/python3.9/site-packages/debug_toolbar/middleware.py", line 74, in __call__
    rendered = toolbar.render_toolbar()
  File "/usr/local/lib/python3.9/site-packages/debug_toolbar/toolbar.py", line 82, in render_toolbar
    return render_to_string("debug_toolbar/base.html", context)
  File "/usr/local/lib/python3.9/site-packages/django/template/loader.py", line 62, in render_to_string
    return template.render(context, request)
  File "/usr/local/lib/python3.9/site-packages/django/template/backends/django.py", line 61, in render
    return self.template.render(context)
  File "/usr/local/lib/python3.9/site-packages/django/template/base.py", line 170, in render
    return self._render(context)
  File "/usr/local/lib/python3.9/site-packages/django/test/utils.py", line 100, in instrumented_test_render
    return self.nodelist.render(context)
  File "/usr/local/lib/python3.9/site-packages/django/template/base.py", line 938, in render
    bit = node.render_annotated(context)
  File "/usr/local/lib/python3.9/site-packages/django/template/base.py", line 905, in render_annotated
    return self.render(context)
  File "/usr/local/lib/python3.9/site-packages/django/template/defaulttags.py", line 315, in render
    return nodelist.render(context)
  File "/usr/local/lib/python3.9/site-packages/django/template/base.py", line 938, in render
    bit = node.render_annotated(context)
  File "/usr/local/lib/python3.9/site-packages/django/template/base.py", line 905, in render_annotated
    return self.render(context)
  File "/usr/local/lib/python3.9/site-packages/django/template/defaulttags.py", line 449, in render
    url = reverse(view_name, args=args, kwargs=kwargs, current_app=current_app)
  File "/usr/local/lib/python3.9/site-packages/django/urls/base.py", line 82, in reverse
    raise NoReverseMatch("%s is not a registered namespace" % key)
django.urls.exceptions.NoReverseMatch: 'djdt' is not a registered namespace
ERROR 2022-12-05 11:52:55,659 django.server.log_message:161- "GET /favicon.ico HTTP/1.1" 500 124920
WARNING 2022-12-05 12:03:22,571 django.request.log_response:224- Not Found: /favicon.ico
WARNING 2022-12-05 12:03:22,575 django.server.log_message:161- "GET /favicon.ico HTTP/1.1" 404 14350
ERROR 2022-12-05 12:03:28,524 django.request.log_response:224- Internal Server Error: /create/
Traceback (most recent call last):
  File "/usr/local/lib/python3.9/site-packages/django/core/handlers/exception.py", line 47, in inner
    response = get_response(request)
  File "/usr/local/lib/python3.9/site-packages/django/core/handlers/base.py", line 181, in _get_response
    response = wrapped_callback(request, *callback_args, **callback_kwargs)
  File "/usr/local/lib/python3.9/site-packages/django/views/generic/base.py", line 70, in view
    return self.dispatch(request, *args, **kwargs)
  File "/usr/local/lib/python3.9/site-packages/django/contrib/auth/mixins.py", line 71, in dispatch
    return super().dispatch(request, *args, **kwargs)
  File "/usr/local/lib/python3.9/site-packages/django/views/generic/base.py", line 98, in dispatch
    return handler(request, *args, **kwargs)
  File "/usr/local/lib/python3.9/site-packages/django/views/generic/edit.py", line 172, in post
    return super().post(request, *args, **kwargs)
  File "/usr/local/lib/python3.9/site-packages/django/views/generic/edit.py", line 142, in post
    return self.form_valid(form)
  File "/app/todolist/views.py", line 34, in form_valid
    return super(TaskCreate, self).form_valid(form)
  File "/usr/local/lib/python3.9/site-packages/django/views/generic/edit.py", line 126, in form_valid
    return super().form_valid(form)
  File "/usr/local/lib/python3.9/site-packages/django/views/generic/edit.py", line 57, in form_valid
    return HttpResponseRedirect(self.get_success_url())
  File "/usr/local/lib/python3.9/site-packages/django/views/generic/edit.py", line 112, in get_success_url
    if self.success_url:
  File "/usr/local/lib/python3.9/site-packages/django/utils/functional.py", line 135, in __wrapper__
    res = func(*self.__args, **self.__kw)
  File "/usr/local/lib/python3.9/site-packages/django/urls/base.py", line 86, in reverse
    return resolver._reverse_with_prefix(view, prefix, *args, **kwargs)
  File "/usr/local/lib/python3.9/site-packages/django/urls/resolvers.py", line 698, in _reverse_with_prefix
    raise NoReverseMatch(msg)
django.urls.exceptions.NoReverseMatch: Reverse for 'task_list' not found. 'task_list' is not a valid view function or pattern name.
ERROR 2022-12-05 12:03:28,654 django.server.log_message:161- "POST /create/ HTTP/1.1" 500 122250
ERROR 2022-12-05 12:10:48,705 django.request.log_response:224- Internal Server Error: /create/
Traceback (most recent call last):
  File "/usr/local/lib/python3.9/site-packages/django/core/handlers/exception.py", line 47, in inner
    response = get_response(request)
  File "/usr/local/lib/python3.9/site-packages/django/core/handlers/base.py", line 204, in _get_response
    response = response.render()
  File "/usr/local/lib/python3.9/site-packages/django/template/response.py", line 105, in render
    self.content = self.rendered_content
  File "/usr/local/lib/python3.9/site-packages/django/template/response.py", line 81, in rendered_content
    template = self.resolve_template(self.template_name)
  File "/usr/local/lib/python3.9/site-packages/django/template/response.py", line 63, in resolve_template
    return select_template(template, using=self.using)
  File "/usr/local/lib/python3.9/site-packages/django/template/loader.py", line 47, in select_template
    raise TemplateDoesNotExist(', '.join(template_name_list), chain=chain)
django.template.exceptions.TemplateDoesNotExist: todolist/task_form.html
ERROR 2022-12-05 12:10:48,748 django.server.log_message:161- "POST /create/ HTTP/1.1" 500 89577
